Workbook

Sheet Resumo (novas abas)
A1: Resumo — abas adicionadas para cruzar com o Banco de Perguntas por Setor
A3: Aba | B3: Origem | C3: Total de perguntas | D3: Predominância de eixo | E3: O que fazer
A4: CPA Atual (por eixo) | B4: Relatorio_CPA_2026_1.csv (instrumento já em uso) | C4: 61 | D4: Eixo 3 (Políticas Acadêmicas) — maioria; Eixo 5 forte em Infraestrutura | E4: Comparar com as perguntas novas para não duplicar
A5: NEAD - EAD | B5: Documento colado pelo Yago (perguntas novas mar/2026 + vigentes até fev/2026) | C5: 18 | D5: Eixo 3, com alguns itens de Eixo 5 (AVA/acesso técnico) | E5: Texto 100% literal — cada pergunta e cada opção de resposta são exatamente o que está no documento do Yago
A6: Onboarding | B6: Documento colado pelo Yago (setor de Empregabilidade/Onboarding) | C6: 10 | D6: Maioria 'Não se aplica / dado cadastral' — são tags, não perguntas avaliativas | E6: Texto 100% literal — inclui nota sobre o item 8 (que é frase de transição, não pergunta própria)
A7: Empregabilidade | B7: Documento colado pelo Yago (Carreira, Fim de Curso, Egresso) | C7: 32 | D7: Eixo 3 (Dimensão 9 — atendimento/apoio ao discente) | E7: Texto 100% literal — numeração e saltos do documento original preservados; duplicatas com o Onboarding sinalizadas
A8: CPA 2024.1 (planilha antiga) | B8: QUESTÕES CPA 2024.1.xlsx — aba PERGUNTAS (visão do aluno) | C8: 109 | D8: Eixo 5 (Dimensão 7) e Eixo 3 (Dimensão 2) — maioria; traz um bloco de conhecimento institucional (Dimensões 1, 3 e 8) e um de autoavaliação do aluno | E8: Texto 100% literal. Cruzada contra todas as abas: ver colunas N a Q (IGUAL / MUITO PARECIDA / NOVA)
A10: Cruzamento — planilha antiga × arquivo atual
A11: Situação | B11: Qtd. de perguntas
A12: IGUAL | B12: =COUNTIF('CPA 2024.1 (planilha antiga)'!N3:N111,A12) -> 17
A13: MUITO PARECIDA | B13: =COUNTIF('CPA 2024.1 (planilha antiga)'!N3:N111,A13) -> 55
A14: NOVA | B14: =COUNTIF('CPA 2024.1 (planilha antiga)'!N3:N111,A14) -> 37
A15: Total | B15: =SUM(B12:B14) -> 109
A17: Perguntas NOVAS por Eixo/Dimensão
A18: Dimensão do SINAES | B18: Novas | C18: Total na planilha antiga
A19: Dimensão 1 — Missão e PDI | B19: =COUNTIFS('CPA 2024.1 (planilha antiga)'!L3:L111,A19,'CPA 2024.1 (planilha antiga)'!N3:N111,"NOVA") -> 2 | C19: =COUNTIF('CPA 2024.1 (planilha antiga)'!L3:L111,A19) -> 3
A20: Dimensão 2 — Ensino, Pesquisa e Extensão | B20: =COUNTIFS('CPA 2024.1 (planilha antiga)'!L3:L111,A20,'CPA 2024.1 (planilha antiga)'!N3:N111,"NOVA") -> 7 | C20: =COUNTIF('CPA 2024.1 (planilha antiga)'!L3:L111,A20) -> 30
A21: Dimensão 3 — Responsabilidade Social | B21: =COUNTIFS('CPA 2024.1 (planilha antiga)'!L3:L111,A21,'CPA 2024.1 (planilha antiga)'!N3:N111,"NOVA") -> 0 | C21: =COUNTIF('CPA 2024.1 (planilha antiga)'!L3:L111,A21) -> 1
A22: Dimensão 4 — Comunicação com a Sociedade | B22: =COUNTIFS('CPA 2024.1 (planilha antiga)'!L3:L111,A22,'CPA 2024.1 (planilha antiga)'!N3:N111,"NOVA") -> 0 | C22: =COUNTIF('CPA 2024.1 (planilha antiga)'!L3:L111,A22) -> 1
A23: Dimensão 5 — Políticas de Pessoal | B23: =COUNTIFS('CPA 2024.1 (planilha antiga)'!L3:L111,A23,'CPA 2024.1 (planilha antiga)'!N3:N111,"NOVA") -> 1 | C23: =COUNTIF('CPA 2024.1 (planilha antiga)'!L3:L111,A23) -> 5
A24: Dimensão 6 — Organização e Gestão | B24: =COUNTIFS('CPA 2024.1 (planilha antiga)'!L3:L111,A24,'CPA 2024.1 (planilha antiga)'!N3:N111,"NOVA") -> 2 | C24: =COUNTIF('CPA 2024.1 (planilha antiga)'!L3:L111,A24) -> 6
A25: Dimensão 7 — Infraestrutura Física | B25: =COUNTIFS('CPA 2024.1 (planilha antiga)'!L3:L111,A25,'CPA 2024.1 (planilha antiga)'!N3:N111,"NOVA") -> 4 | C25: =COUNTIF('CPA 2024.1 (planilha antiga)'!L3:L111,A25) -> 19
A26: Dimensão 8 — Planejamento e Avaliação | B26: =COUNTIFS('CPA 2024.1 (planilha antiga)'!L3:L111,A26,'CPA 2024.1 (planilha antiga)'!N3:N111,"NOVA") -> 1 | C26: =COUNTIF('CPA 2024.1 (planilha antiga)'!L3:L111,A26) -> 8
A27: Dimensão 9 — Atendimento aos Discentes | B27: =COUNTIFS('CPA 2024.1 (planilha antiga)'!L3:L111,A27,'CPA 2024.1 (planilha antiga)'!N3:N111,"NOVA") -> 2 | C27: =COUNTIF('CPA 2024.1 (planilha antiga)'!L3:L111,A27) -> 10
A28: Dimensão 10 — Sustentabilidade Financeira | B28: =COUNTIFS('CPA 2024.1 (planilha antiga)'!L3:L111,A28,'CPA 2024.1 (planilha antiga)'!N3:N111,"NOVA") -> 0 | C28: =COUNTIF('CPA 2024.1 (planilha antiga)'!L3:L111,A28) -> 0
A29: revisar* | B29: =COUNTIFS('CPA 2024.1 (planilha antiga)'!L3:L111,A29,'CPA 2024.1 (planilha antiga)'!N3:N111,"NOVA") -> 18 | C29: =COUNTIF('CPA 2024.1 (planilha antiga)'!L3:L111,A29) -> 23
A30: Não se aplica* | B30: =COUNTIFS('CPA 2024.1 (planilha antiga)'!L3:L111,A30,'CPA 2024.1 (planilha antiga)'!N3:N111,"NOVA") -> 0 | C30: =COUNTIF('CPA 2024.1 (planilha antiga)'!L3:L111,A30) -> 3
A31: Obs.: "revisar*" soma todas as classificações marcadas como revisar (inclui a "Infraestrutura Virtual (11)" da planilha antiga, que não é dimensão do SINAES).

Sheet CPA Atual (por eixo)
A1: Todas as perguntas em uso no instrumento vigente da CPA, com a modalidade em que cada uma é aplicada — texto 100% literal. Colunas A a J seguem o mesmo padrão do Banco de Perguntas por Setor (coláveis direto); coluna K (Modalidade) é extra, vinda do arquivo CPA_geral_quant.csv. Coluna L (Dimensão do SINAES) adicionada em set/2026 a partir do Eixo da coluna E; células em vermelho = "revisar".
A2: Nº | B2: Pergunta proposta pelo setor | C2: Tipo de resposta | D2: Opções / Escala detalhada | E2: Eixo do SINAES relacionado | F2: Setor solicitante | G2: Responsável pelo setor | H2: Data da solicitação | I2: Status | J2: Observações / Justificativa | K2: Modalidade | L2: Dimensão do SINAES
A3: 1 | B3: Avaliações e conteúdos apresentados | C3: Escala 1 a 5 | D3: Escala 1 a 5 | E3: 3. Políticas Acadêmicas | F3: CPA (instrumento vigente) | I3: Já em uso — instrumento 2026.1 | J3: Pesquisa: CPA - Conteúdo das Disciplinas | K3: EAD | L3: Dimensão 2 — Ensino, Pesquisa e Extensão
A4: 2 | B4: Conteúdo das videoaulas | C4: Escala 1 a 5 | D4: Escala 1 a 5 | E4: 3. Políticas Acadêmicas | F4: CPA (instrumento vigente) | I4: Já em uso — instrumento 2026.1 | J4: Pesquisa: CPA - Conteúdo das Disciplinas | K4: EAD | L4: Dimensão 2 — Ensino, Pesquisa e Extensão
A5: 3 | B5: Estudos de caso | C5: Escala 1 a 5 | D5: Escala 1 a 5 | E5: 3. Políticas Acadêmicas | F5: CPA (instrumento vigente) | I5: Já em uso — instrumento 2026.1 | J5: Pesquisa: CPA - Conteúdo das Disciplinas | K5: EAD | L5: Dimensão 2 — Ensino, Pesquisa e Extensão
A6: 4 | B6: Materiais escritos (textos, infográficos, mapas etc.) | C6: Escala 1 a 5 | D6: Escala 1 a 5 | E6: 3. Políticas Acadêmicas | F6: CPA (instrumento vigente) | I6: Já em uso — instrumento 2026.1 | J6: Pesquisa: CPA - Conteúdo das Disciplinas | K6: EAD | L6: Dimensão 2 — Ensino, Pesquisa e Extensão
A7: 5 | B7: Avaliações e conteúdos apresentados | C7: Escala 1 a 5 | D7: Escala 1 a 5 | E7: 3. Políticas Acadêmicas | F7: CPA (instrumento vigente) | I7: Já em uso — instrumento 2026.1 | J7: Pesquisa: CPA - Conteúdo das Disciplinas | K7: Presencial | L7: Dimensão 2 — Ensino, Pesquisa e Extensão
A8: 6 | B8: Conteúdo das videoaulas | C8: Escala 1 a 5 | D8: Escala 1 a 5 | E8: 3. Políticas Acadêmicas | F8: CPA (instrumento vigente) | I8: Já em uso — instrumento 2026.1 | J8: Pesquisa: CPA - Conteúdo das Disciplinas | K8: Presencial | L8: Dimensão 2 — Ensino, Pesquisa e Extensão
A9: 7 | B9: Estudos de caso | C9: Escala 1 a 5 | D9: Escala 1 a 5 | E9: 3. Políticas Acadêmicas | F9: CPA (instrumento vigente) | I9: Já em uso — instrumento 2026.1 | J9: Pesquisa: CPA - Conteúdo das Disciplinas | K9: Presencial | L9: Dimensão 2 — Ensino, Pesquisa e Extensão
A10: 8 | B10: Materiais escritos (textos, infográficos, mapas etc.) | C10: Escala 1 a 5 | D10: Escala 1 a 5 | E10: 3. Políticas Acadêmicas | F10: CPA (instrumento vigente) | I10: Já em uso — instrumento 2026.1 | J10: Pesquisa: CPA - Conteúdo das Disciplinas | K10: Presencial | L10: Dimensão 2 — Ensino, Pesquisa e Extensão
A11: 9 | B11: Avaliações e conteúdos apresentados | C11: Escala 1 a 5 | D11: Escala 1 a 5 | E11: 3. Políticas Acadêmicas | F11: CPA (instrumento vigente) | I11: Já em uso — instrumento 2026.1 | J11: Pesquisa: CPA - Conteúdo das Disciplinas | K11: Semipresencial | L11: Dimensão 2 — Ensino, Pesquisa e Extensão
A12: 10 | B12: Conteúdo das videoaulas | C12: Escala 1 a 5 | D12: Escala 1 a 5 | E12: 3. Políticas Acadêmicas | F12: CPA (instrumento vigente) | I12: Já em uso — instrumento 2026.1 | J12: Pesquisa: CPA - Conteúdo das Disciplinas | K12: Semipresencial | L12: Dimensão 2 — Ensino, Pesquisa e Extensão
A13: 11 | B13: Estudos de caso | C13: Escala 1 a 5 | D13: Escala 1 a 5 | E13: 3. Políticas Acadêmicas | F13: CPA (instrumento vigente) | I13: Já em uso — instrumento 2026.1 | J13: Pesquisa: CPA - Conteúdo das Disciplinas | K13: Semipresencial | L13: Dimensão 2 — Ensino, Pesquisa e Extensão
A14: 12 | B14: Materiais escritos (textos, infográficos, mapas etc.) | C14: Escala 1 a 5 | D14: Escala 1 a 5 | E14: 3. Políticas Acadêmicas | F14: CPA (instrumento vigente) | I14: Já em uso — instrumento 2026.1 | J14: Pesquisa: CPA - Conteúdo das Disciplinas | K14: Semipresencial | L14: Dimensão 2 — Ensino, Pesquisa e Extensão
... A155: 153 | B155: Deixe aqui seu comentário sobre seu tutor | C155: Texto livre | D155: Texto livre | E155: 3. Políticas Acadêmicas | F155: CPA (instrumento vigente) | I155: Já em uso — instrumento 2026.1 | J155: Pesquisa: CPA - Tutores — não consta no arquivo quant (é campo aberto, não entra em média) | K155: EAD, Presencial, Semipresencial | L155: Dimensão 2 — Ensino, Pesquisa e Extensão

Sheet NEAD - EAD
A1: Texto 100% literal do documento colado pelo Yago (NEAD). Inclui o conjunto novo (a partir de março/2026) e o conjunto vigente até fev/2026 que será substituído. Nada foi resumido ou reescrito.
A2: Nº | B2: Pergunta proposta pelo setor | C2: Tipo de resposta | D2: Opções / Escala detalhada | E2: Eixo do SINAES relacionado | F2: Setor solicitante | G2: Responsável pelo setor | H2: Data da solicitação | I2: Status | J2: Observações / Justificativa
A3: 1 | B3: Sobre o material escrito (e-books/textos), como você avalia a clareza da linguagem e a organização das ideias? | C3: Escala 1 a 5 | D3: Muito insatisfeito | Insatisfeito | Parcialmente satisfeito | Satisfeito | Muito satisfeito | E3: 3. Políticas Acadêmicas | F3: NEAD (EAD) | I3: Proposta — vigente a partir de março/2026
A4: 2 | B4: As videoaulas do professor (conteúdo gravado) complementam bem o material escrito ou são repetitivas? | C4: Escala 1 a 5 | D4: 1. São muito repetitivas (não agregam) | 2. Pouco complementares | 3. Parcialmente complementar | 4. Complementam bem | 5. São essenciais e complementares | E4: 3. Políticas Acadêmicas | F4: NEAD (EAD) | I4: Proposta — vigente a partir de março/2026
A5: 3 | B5: Sobre o material escrito (textos disponibilizados na disciplina), como você avalia a profundidade e a quantidade das informações apresentadas? | C5: Escala 1 a 5 | D5: Muito resumido (faltam detalhes importantes) | Resumido (poderia aprofundar mais) | Na medida certa (equilibrado em extensão e profundidade) | Extenso (traz muitos detalhes, alguns pouco relevantes) | Muito extenso (excesso de informações, difícil acompanhar) | E5: 3. Políticas Acadêmicas | F5: NEAD (EAD) | I5: Proposta — vigente a partir de março/2026
A6: 4 | B6: Como você avalia a facilidade de leitura e a aparência visual (design) dos materiais? (Considere cores, fontes e organização visual) | C6: Escala 1 a 5 | D6: Muito insatisfeito | Insatisfeito | Parcialmente satisfeito | Satisfeito | Muito satisfeito | E6: 3. Políticas Acadêmicas | F6: NEAD (EAD) | I6: Proposta — vigente a partir de março/2026
A7: 5 | B7: Você encontrou dificuldades técnicas para acessar ou carregar os materiais? | C7: Múltipla escolha (única) | D7: Sim, frequentemente (lentidão/erros) | Às vezes | Raramente | Nunca tive problemas | E7: 5. Infraestrutura Física | F7: NEAD (EAD) | I7: Proposta — vigente a partir de março/2026
A8: 6 | B8: Em qual dispositivo você consome a maior parte do conteúdo? | C8: Múltipla escolha (única) | D8: Celular | Computador / Notebook | Material impresso | Tablet / TV | E8: Não se aplica / dado cadastral | F8: NEAD (EAD) | I8: Proposta — vigente a partir de março/2026
A9: 7 | B9: No Ambiente Virtual de Aprendizagem (AVA), quão fácil foi encontrar o que você precisava? | C9: Escala 1 a 5 | D9: Muito difícil | Difícil | Indiferente | Fácil | Muito fácil | E9: 5. Infraestrutura Física | F9: NEAD (EAD) | I9: Proposta — vigente a partir de março/2026
A10: 8 | B10: Para aprender de verdade: Quais desses formatos você considera MAIS EFICAZES para o seu estudo? (Selecione até 3) | C10: Múltipla escolha (várias, até 3) | D10: Capítulos de livros (Biblioteca Virtual) | Videoaulas do professor | Artigos científicos (leitura técnica) | Materiais externos (YouTube/Links curados) | Podcasts / Áudios | Resumos em texto escrito | Infográficos/Mapas mentais | E10: 3. Políticas Acadêmicas | F10: NEAD (EAD) | I10: Proposta — vigente a partir de março/2026
A11: 9 | B11: Sobre as lives (aulas ao vivo): Qual dia da semana você gostaria que acontecesse suas aulas ao vivo? (Marque até 2 alternativas) | C11: Múltipla escolha (várias, até 2) | D11: Segunda-feira | Terça-feira | Quarta-feira | Quinta-feira | Sexta-feira | E11: Não se aplica / dado cadastral | F11: NEAD (EAD) | I11: Proposta — vigente a partir de março/2026
A12: 10 | B12: Em que medida o conteúdo disponibilizado (material escrito e videoaulas) é útil para sua prática profissional, para os estudos acadêmicos e para o uso no dia a dia? | C12: Escala 1 a 5 | D12: Nada útil (não consigo aplicar em nenhuma situação) | Pouco útil (aplicável raramente) | Moderadamente útil (aplicável em alguns casos específicos) | Útil (aplicável em várias situações, inclusive no cotidiano) | Muito útil (essencial e diretamente aplicável à minha prática profissional, estudos e vida diária) | E12: 3. Políticas Acadêmicas | F12: NEAD (EAD) | I12: Proposta — vigente a partir de março/2026
A13: 11 | B13: De 0 a 10, o quanto você recomendaria a qualidade deste material para um colega? | C13: NPS (0 a 10) | D13: 0 a 10 (Net Promoter Score) | E13: 1. Planejamento e Avaliação Institucional | F13: NEAD (EAD) | I13: Proposta — vigente a partir de março/2026
A14: 12 | B14: O que falta para sua experiência ser nota 10? | C14: Aberta (texto livre) | D14: Espaço para texto livre: sugestões de melhoria, críticas ou elogios específicos sobre usabilidade e conteúdo | E14: 1. Planejamento e Avaliação Institucional | F14: NEAD (EAD) | I14: Proposta — vigente a partir de março/2026
... A20: 18 | B20: Queremos a sua opinião… Escreva algum comentário ou sugestão sobre os pontos avaliados. | C20: Aberta (texto livre) | D20: Sem limite de caracteres | E20: 3. Políticas Acadêmicas | F20: NEAD (EAD) | I20: Vigente até fev/2026 — a ser substituída

Sheet Onboarding
A1: Texto 100% literal do bloco 'Onboarding Identificação' do documento colado pelo Yago (setor de Empregabilidade). Nota do documento original: dados do estudante (nome, RA, curso, modalidade, UF, contato) precisam vir integrados na pesquisa e no dash, sempre tagueando o aluno.
A2: Nº | B2: Pergunta proposta pelo setor | C2: Tipo de resposta | D2: Opções / Escala detalhada | E2: Eixo do SINAES relacionado | F2: Setor solicitante | G2: Responsável pelo setor | H2: Data da solicitação | I2: Status | J2: Observações / Justificativa
A3: 1 | B3: Você possui alguma deficiência? | C3: Múltipla escolha (única) | D3: Sim, física (ex.: mobilidade, locomoção) | Sim, sensorial (ex.: auditiva, visual) | Sim, intelectual ou múltipla | Não | E3: 3. Políticas Acadêmicas | F3: Onboarding | I3: Proposta — coleta no onboarding do aluno | J3: acessibilidade — dimensão 9
A4: 2 | B4: Qual é a sua cor ou raça? | C4: Múltipla escolha (única) | D4: Branca | Preta | Parda | Amarela | Indígena | Prefiro não responder | E4: Não se aplica / dado cadastral | F4: Onboarding | I4: Proposta — coleta no onboarding do aluno
A5: 3 | B5: Qual o seu principal objetivo ao ingressar na faculdade: | C5: Múltipla escolha (única) | D5: Conseguir o primeiro emprego. | Migrar de área. | Crescer profissionalmente. | Aumentar a renda. | Ser empreendedor | Outros. | E5: Não se aplica / dado cadastral | F5: Onboarding | I5: Proposta — coleta no onboarding do aluno
A6: 4 | B6: Atualmente, você está trabalhando? | C6: Múltipla escolha (única) | D6: Sim, com carteira assinada. | Sim, sem carteira assinada. | Sim, sou estagiario | Sim, sou autônomo / MEI. | Não estou trabalhando. | Não estou trabalhando por opção. | E6: Não se aplica / dado cadastral | F6: Onboarding | I6: Proposta — coleta no onboarding do aluno
A7: 4.1 | B7: Se sim, qual é o nome da atual empresa onde você trabalha? | C7: Aberta (texto livre) | D7: Resposta aberta | E7: Não se aplica / dado cadastral | F7: Onboarding | I7: Proposta — coleta no onboarding do aluno
A8: 5 | B8: Qual sua renda mensal atual? | C8: Aberta (texto livre) | D8: Resposta aberta — *Pesquisa sigilosa, utilizada apenas para fins estatísticos, sem identificação do usuário | E8: Não se aplica / dado cadastral | F8: Onboarding | I8: Proposta — coleta no onboarding do aluno
A9: 6 | B9: Você trabalha na área do seu curso? | C9: Múltipla escolha (única) | D9: Sim | Não | E9: 3. Políticas Acadêmicas | F9: Onboarding | I9: Proposta — coleta no onboarding do aluno | J9: relação curso-mercado, dimensão 9
A10: 7 | B10: Qual a empresa dos seus sonhos? | C10: Aberta (texto livre) | D10: Resposta aberta — nota do setor: "Importante para mapear aspirações e direcionar parcerias" | E10: Não se aplica / dado cadastral | F10: Onboarding | I10: Proposta — coleta no onboarding do aluno | J10: o texto após a pergunta parece anotação interna do setor, não parte do que é exibido ao aluno — confirmar com o NEAD/Empregabilidade
A11: 8 | B11: Estamos mapeando oportunidades que exigem conhecimento em outros idiomas, como vagas de emprego ou programas internacionais. Por isso, responda: | C11: (texto de transição, sem opções própria) | D11: — ver pergunta 9 | E11: Não se aplica / dado cadastral | F11: Onboarding | I11: Proposta — coleta no onboarding do aluno | J11: no documento original, o item 8 é uma frase de transição para a pergunta 9, não uma pergunta com resposta própria
A12: 9 | B12: Com qual das opções abaixo você mais se identifica? | C12: Múltipla escolha (única) | D12: Falo e entendo bem inglês | Falo e entendo bem espanhol | Falo e entendo bem outro idioma (ex: francês, alemão, etc.) | Tenho noções básicas de algum idioma | Nunca estudei outro idioma | E12: Não se aplica / dado cadastral | F12: Onboarding | I12: Proposta — coleta no onboarding do aluno

Sheet Empregabilidade
A1: Texto 100% literal do documento colado pelo Yago (setor de Empregabilidade) — reúne as 3 etapas na ordem em que aparecem no original: Pesquisa semestral - Carreira, Empregabilidade — Fim do Curso, Pesquisa Egresso 120 dias. Numeração e eventuais saltos (ex.: falta o item "4" na etapa Carreira) foram preservados exatamente como no documento fonte.
A2: Nº | B2: Pergunta proposta pelo setor | C2: Tipo de resposta | D2: Opções / Escala detalhada | E2: Eixo do SINAES relacionado | F2: Setor solicitante | G2: Responsável pelo setor | H2: Data da solicitação | I2: Status | J2: Observações / Justificativa
A3: 1 | B3: Você possui alguma deficiência? | C3: Múltipla escolha (única) | D3: Sim, física (ex.: mobilidade, locomoção) | Sim, sensorial (ex.: auditiva, visual) | Sim, intelectual ou múltipla | Não | E3: 3. Políticas Acadêmicas | F3: Empregabilidade | I3: Proposta — Pesquisa semestral - Carreira | J3: repete a pergunta 1 do Onboarding
A4: 2 | B4: Qual é a sua cor ou raça? | C4: Múltipla escolha (única) | D4: Branca | Preta | Parda | Amarela | Indígena | Prefiro não responder | E4: Não se aplica / dado cadastral | F4: Empregabilidade | I4: Proposta — Pesquisa semestral - Carreira | J4: repete a pergunta 2 do Onboarding
A5: 3 | B5: Atualmente, você está trabalhando? | C5: Múltipla escolha (única) | D5: Sim, com carteira assinada. | Sim, sem carteira assinada. | Sim, sou estagiario | Sim, sou autônomo / MEI. | Não estou trabalhando. | Não estou trabalhando por opção. | E5: Não se aplica / dado cadastral | F5: Empregabilidade | I5: Proposta — Pesquisa semestral - Carreira | J5: repete a pergunta 4 do Onboarding
A6: 3.1 | B6: Se sim, qual é o nome da atual empresa onde você trabalha? | C6: Aberta (texto livre) | D6: Resposta aberta | E6: Não se aplica / dado cadastral | F6: Empregabilidade | I6: Proposta — Pesquisa semestral - Carreira | J6: numeração "3,1" está assim no documento original
A7: 5 | B7: Qual sua renda mensal atual? | C7: Aberta (texto livre) | D7: Resposta aberta — *Pesquisa sigilosa, utilizada apenas para fins estatísticos, sem identificação do usuário | E7: Não se aplica / dado cadastral | F7: Empregabilidade | I7: Proposta — Pesquisa semestral - Carreira | J7: não existe item "4" no documento original — numeração pula de 3.1 para 5
A8: 6 | B8: Você trabalha na área do seu curso? | C8: Múltipla escolha (única) | D8: Sim | Não | E8: 3. Políticas Acadêmicas | F8: Empregabilidade | I8: Proposta — Pesquisa semestral - Carreira
A9: 7 | B9: Qual a empresa dos seus sonhos? | C9: Aberta (texto livre) | D9: Resposta aberta | E9: Não se aplica / dado cadastral | F9: Empregabilidade | I9: Proposta — Pesquisa semestral - Carreira
A10: 8 | B10: Qual a sua principal fonte de recurso para pagamento das mensalidades? | C10: Múltipla escolha (única) | D10: Suporte da Família. | Trabalho/Estágio próprio. | Financiamento privado. | FIES / PROUNI / Bolsista | E10: Não se aplica / dado cadastral | F10: Empregabilidade | I10: Proposta — Pesquisa semestral - Carreira
A11: 9 | B11: Quais são as maiores dificuldades que você enfrenta hoje para conseguir ou melhorar seu emprego? Selecione uma ou mais opções. | C11: Múltipla escolha (várias) | D11: Falta de experiência. | Falta de networking (conexões profissionais). | Baixa qualificação técnica. | Dificuldade em entrevistas ou processos seletivos. | Falta de tempo para se dedicar à carreira. | E11: 3. Políticas Acadêmicas | F11: Empregabilidade | I11: Proposta — Pesquisa semestral - Carreira | J11: apoio à empregabilidade, dimensão 9
A12: 10 | B12: Estamos mapeando oportunidades que exigem conhecimento em outros idiomas, como vagas de emprego ou programas internacionais. Por isso, responda: Com qual das opções abaixo você mais se identifica? | C12: Múltipla escolha (única) | D12: Falo e entendo bem inglês | Falo e entendo bem espanhol | Falo e entendo bem outro idioma (ex: francês, alemão, etc.) | Tenho noções básicas de algum idioma | Nunca estudei outro idioma | E12: Não se aplica / dado cadastral | F12: Empregabilidade | I12: Proposta — Pesquisa semestral - Carreira | J12: repete a pergunta 8+9 do Onboarding
A13: 11 | B13: Você possui alguma sugestão, experiência ou comentário sobre sua trajetória de desenvolvimento profissional, empregabilidade e apoio recebido pela UniFECAF? | C13: Aberta (texto livre) | D13: Resposta aberta | E13: 3. Políticas Acadêmicas | F13: Empregabilidade | I13: Proposta — Pesquisa semestral - Carreira
A14: 1 | B14: Atualmente, você está trabalhando? | C14: Múltipla escolha (única) | D14: Sim, com carteira assinada. | Sim, sem carteira assinada. | Sim, sou estagiario | Sim, sou autônomo / MEI. | Não estou trabalhando. | Não estou trabalhando por opção. | E14: Não se aplica / dado cadastral | F14: Empregabilidade | I14: Proposta — Empregabilidade — Fim do Curso
A15: 2 | B15: Se sim, qual é o nome da atual empresa onde você trabalha? | C15: Aberta (texto livre) | D15: Resposta aberta | E15: Não se aplica / dado cadastral | F15: Empregabilidade | I15: Proposta — Empregabilidade — Fim do Curso
A16: 3 | B16: Qual sua renda mensal atual? | C16: Aberta (texto livre) | D16: Resposta aberta — *Pesquisa sigilosa, utilizada apenas para fins estatísticos, sem identificação do usuário | E16: Não se aplica / dado cadastral | F16: Empregabilidade | I16: Proposta — Empregabilidade — Fim do Curso
A17: 4 | B17: Você conseguiu um emprego ou trocou de emprego durante o curso? | C17: Múltipla escolha (única) | D17: Sim | Não | E17: 3. Políticas Acadêmicas | F17: Empregabilidade | I17: Proposta — Empregabilidade — Fim do Curso
A18: 5 | B18: Se sim, esse novo emprego foi conquistado: | C18: Múltipla escolha (única) | D18: Por plataformas / sites fora da faculdade. | Por indicação de conhecidos. | Por eventos/feiras realizados na UniFECAF. | Por empresas parceiras / plataforma de vagas da UniFECAF. | Outros | E18: 3. Políticas Acadêmicas | F18: Empregabilidade | I18: Proposta — Empregabilidade — Fim do Curso | J18: mede ação institucional — dimensão 9
A19: 6 | B19: Desde o início do curso na UniFECAF, como sua situação profissional se desenvolveu? | C19: Múltipla escolha (única) | D19: Houve grande crescimento profissional. | Houve crescimento profissional. | Não houve mudanças relevantes. | Houve retrocesso profissional. | E19: 3. Políticas Acadêmicas | F19: Empregabilidade | I19: Proposta — Empregabilidade — Fim do Curso
A20: 7 | B20: O curso contribuiu para: Selecione uma ou mais opções. | C20: Múltipla escolha (várias) | D20: Conseguir uma recolocação no mercado de trabalho. | Ter uma promoção ou aumento salarial. | Fazer uma transição de carreira | Desenvolver novas competências. | Empreender. | E20: 3. Políticas Acadêmicas | F20: Empregabilidade | I20: Proposta — Empregabilidade — Fim do Curso
A21: 8 | B21: Após a conclusão do curso, você pretende: Selecione uma ou mais opções. | C21: Múltipla escolha (várias) | D21: Permanecer no emprego atual. | Buscar nova oportunidade na área. | Empreender. | Continuar os estudos (pós-graduação). | E21: Não se aplica / dado cadastral | F21: Empregabilidade | I21: Proposta — Empregabilidade — Fim do Curso
A22: 9 | B22: Você possui alguma sugestão, experiência ou comentário sobre sua trajetória de desenvolvimento profissional, empregabilidade e apoio recebido pela UniFECAF? | C22: Aberta (texto livre) | D22: Resposta aberta | E22: 3. Políticas Acadêmicas | F22: Empregabilidade | I22: Proposta — Empregabilidade — Fim do Curso
A23: 1 | B23: Atualmente, você está trabalhando? | C23: Múltipla escolha (única) | D23: Sim, com carteira assinada. | Sim, sem carteira assinada. | Sim, sou estagiario | Sim, sou autônomo / MEI. | Não estou trabalhando. | Não estou trabalhando por opção. | E23: Não se aplica / dado cadastral | F23: Empregabilidade | I23: Proposta — Pesquisa Egresso — 120 dias após formado
A24: 2 | B24: Se sim, qual é o nome da atual empresa onde você trabalha? | C24: Aberta (texto livre) | D24: Resposta aberta | E24: Não se aplica / dado cadastral | F24: Empregabilidade | I24: Proposta — Pesquisa Egresso — 120 dias após formado
A25: 3 | B25: Qual sua renda mensal atual? | C25: Aberta (texto livre) | D25: Resposta aberta — *Pesquisa sigilosa, utilizada apenas para fins estatísticos, sem identificação do usuário | E25: Não se aplica / dado cadastral | F25: Empregabilidade | I25: Proposta — Pesquisa Egresso — 120 dias após formado
A26: 4 | B26: Após concluir o curso, em quanto tempo você conseguiu sua primeira oportunidade? | C26: Múltipla escolha (única) | D26: Já estava empregado quando terminei o curso. | Até 30 dias. | De 31 a 60 dias. | De 61 a 120 dias. | Ainda não consegui. | E26: 3. Políticas Acadêmicas | F26: Empregabilidade | I26: Proposta — Pesquisa Egresso — 120 dias após formado | J26: indicador de efetividade
A27: 5 | B27: Essa oportunidade foi: | C27: Múltipla escolha (única) | D27: Efetivação de estágio. | Novo emprego. | Promoção no emprego atual. | Início de negócio próprio. | Não se aplica. | E27: 3. Políticas Acadêmicas | F27: Empregabilidade | I27: Proposta — Pesquisa Egresso — 120 dias após formado
A28: 6 | B28: Quais ações da faculdade contribuíram para sua empregabilidade? Selecione uma ou mais opções. | C28: Múltipla escolha (várias) | D28: Estágio supervisionado. | Eventos e feiras de carreira. | Parcerias com empresas. | Projetos práticos. | Mentorias de Carreira | Portal de vagas exclusivo UniFECAF. | E28: 3. Políticas Acadêmicas | F28: Empregabilidade | I28: Proposta — Pesquisa Egresso — 120 dias após formado | J28: a mais diretamente avaliativa do bloco — mede ação institucional, dimensão 9
A29: 7 | B29: Após concluir sua graduação na UniFECAF, você deu continuidade aos seus estudos? | C29: Múltipla escolha (única) | D29: Sim. | Não. | E29: 3. Políticas Acadêmicas | F29: Empregabilidade | I29: Proposta — Pesquisa Egresso — 120 dias após formado
A30: 8 | B30: Se sim, qual modalidade de formação você está cursando ou já cursou após a formação na graduação? | C30: Múltipla escolha (única) | D30: Pós-graduação / Especialização. | MBA. | Segunda graduação. | Mestrado. | Doutorado. | Cursos livres / aperfeiçoamento. | Certificações profissionais. | Outro: ____________ | E30: Não se aplica / dado cadastral | F30: Empregabilidade | I30: Proposta — Pesquisa Egresso — 120 dias após formado
A31: 9 | B31: A instituição em que você realiza ou realizou essa formação é: | C31: Múltipla escolha (única) | D31: UniFECAF. | Outra instituição. | E31: Não se aplica / dado cadastral | F31: Empregabilidade | I31: Proposta — Pesquisa Egresso — 120 dias após formado
A32: 10 | B32: Qual o nome da instituição? | C32: Aberta (texto livre) | D32: Resposta aberta | E32: Não se aplica / dado cadastral | F32: Empregabilidade | I32: Proposta — Pesquisa Egresso — 120 dias após formado
A33: 11 | B33: Qual modalidade: | C33: Múltipla escolha (única) | D33: EAD | Semipresencial | Presencial. | E33: Não se aplica / dado cadastral | F33: Empregabilidade | I33: Proposta — Pesquisa Egresso — 120 dias após formado
A34: 12 | B34: Qual foi o principal motivo para continuar seus estudos? | C34: Múltipla escolha (única) | D34: Ter crescimento profissional. | Ter um aumento salarial. | Mudança de área. | Exigência do mercado. | Desenvolvimento acadêmico. | Interesse pessoal. | E34: Não se aplica / dado cadastral | F34: Empregabilidade | I34: Proposta — Pesquisa Egresso — 120 dias após formado

Sheet CPA 2024.1 (planilha antiga)
A1: Perguntas da aba PERGUNTAS do arquivo QUESTÕES CPA 2024.1 (visão do aluno) — texto 100% literal, incluindo erros de digitação e numeração originais. A aba "Professores" do arquivo antigo não foi incluída (decisão do Yago). Eixo/Dimensão: respeita a Dimensão da planilha antiga; onde ela não existia, a classificação é indicada na coluna M. Situação: IGUAL = mesmo texto (diferença só de numeração, maiúscula ou pontuação) · MUITO PARECIDA = mesmo tema/objetivo com redação ou escala diferente · NOVA = não há nada parecido em nenhuma aba do arquivo atual.
A2: Nº | B2: Bloco na planilha antiga | C2: Enunciado do bloco | D2: Pergunta (texto literal) | E2: Tipo de resposta | F2: Opções / Escala (literal da fonte) | G2: Código da pergunta (original) | H2: Indicador (original) | I2: Dimensão (original) | J2: OBS (original) | K2: Eixo do SINAES | L2: Dimensão do SINAES | M2: Origem da classificação | N2: Situação no cruzamento | O2: Pergunta equivalente no arquivo atual (literal) | P2: Onde está (aba — linha) | Q2: Observações do cruzamento | R2: Linha na planilha antiga
A3: 1 | B3: AVALIAÇÃO GERAL - SATISFAÇÃO GERAL 134 | D3: 1 - Em uma escala de 0 a 10, o quanto você recomendaria a UniFECAF a um amigo ou familiar? | E3: Escala 0 a 10 | F3: 0 a 10 — escala citada no próprio enunciado; a planilha não traz rótulos | G3: 448 | K3: 1. Planejamento e Avaliação Institucional | L3: Dimensão 8 — Planejamento e Avaliação | M3: Classificado pela CPA (planilha antiga sem dimensão): segue a CPA Atual (Recomenda a UniFECAF → Eixo 1) | N3: MUITO PARECIDA | O3: Recomenda a UniFECAF para um amigo ou familiar | P3: CPA Atual (por eixo) — linha 131 (repete nas linhas 134 e 137) | Q3: Mesmo conteúdo; a antiga usa escala 0 a 10, a atual 1 a 5. | R3: 3
A4: 2 | B4: AVALIAÇÃO GERAL - SATISFAÇÃO GERAL 134 | D4: 2 - Em uma escala de 0 a 10, o quanto você está satisfeito(a) com a coordenação do seu Curso? | E4: Escala 0 a 10 | F4: 0 a 10 — escala citada no próprio enunciado; a planilha não traz rótulos | G4: 449 | H4: AVALIAÇÃO DO COORDENADOR | K4: 4. Políticas de Gestão | L4: Dimensão 6 — Organização e Gestão | M4: Classificado pela CPA (planilha antiga sem dimensão): coordenação = gestão (segue a CPA Atual, Eixo 4) | N4: MUITO PARECIDA | O4: Avalia o suporte e a gestão da coordenação do seu curso | P4: CPA Atual (por eixo) — linha 130 (repete nas linhas 133 e 135) | Q4: Mesmo conteúdo; escala diferente. | R4: 4
A5: 3 | B5: AVALIAÇÃO GERAL - SATISFAÇÃO GERAL 134 | D5: 3 - Em uma escala de 0 a 10, o quanto você está satisfeito(a) com os professores da UniFECAF? | E5: Escala 0 a 10 | F5: 0 a 10 — escala citada no próprio enunciado; a planilha não traz rótulos | G5: 450 | H5: AVALIAÇÃO DO PROFESSOR | K5: 3. Políticas Acadêmicas | L5: Dimensão 2 — Ensino, Pesquisa e Extensão | M5: Classificado pela CPA (planilha antiga sem dimensão): docentes/ensino (segue a CPA Atual, Eixo 3) | N5: MUITO PARECIDA | O5: Avalia a qualidade e didática dos professores Professores da UniFECAF | P5: CPA Atual (por eixo) — linha 129 (repete na linha 132) CPA Atual (por eixo) — linha 136 | Q5: Mesmo conteúdo; escala diferente. | R5: 5
A6: 4 | B6: AVALIAÇÃO GERAL - SATISFAÇÃO GERAL 134 | D6: 4 - Em uma escala de 0 a 10, o quanto você está satisfeito(a) com o atendimento dos funcionários da UniFECAF? | E6: Escala 0 a 10 | F6: 0 a 10 — escala citada no próprio enunciado; a planilha não traz rótulos | G6: 451 | K6: 4. Políticas de Gestão | L6: Dimensão 5 — Políticas de Pessoal | M6: Classificado pela CPA (planilha antiga sem dimensão): atendimento de funcionários = corpo técnico-administrativo | N6: MUITO PARECIDA | O6: Como você avalia o comprometimento da equipe técnico-administrativa que atende você (secretaria, TI, biblioteca)? | P6: Perguntas Propostas por Eixo — linha 28 (pergunta candidata, ainda não aprovada) | Q6: Na CPA Atual o atendimento é avaliado setor a setor, não de forma geral. | R6: 6
A7: 5 | B7: AVALIAÇÃO GERAL - SATISFAÇÃO GERAL 134 | D7: 5 - Em uma escala de 0 a 10, o quanto você está satisfeito(a) com a infraestrutura física da UniFECAF? | E7: Escala 0 a 10 | F7: 0 a 10 — escala citada no próprio enunciado; a planilha não traz rótulos | G7: 452 | H7: INFRAESTRUTURA TECNOLÓGICA | K7: 5. Infraestrutura Física | L7: Dimensão 7 — Infraestrutura Física | M7: Classificado pela CPA (planilha antiga sem dimensão) | N7: NOVA | Q7: Não há pergunta de satisfação GERAL com a infraestrutura física; hoje ela é avaliada item a item (CPA Atual linhas 24–83). | R7: 7
A8: 6 | B8: AVALIAÇÃO GERAL - SATISFAÇÃO GERAL 134 | D8: 6 - Em uma escala de 0 a 10, o quanto você está satisfeito(a) com a infraestrutura tecnológica da UniFECAF? | E8: Escala 0 a 10 | F8: 0 a 10 — escala citada no próprio enunciado; a planilha não traz rótulos | G8: 458 | H8: INFRAESTRUTURA TECNOLÓGICA | K8: 5. Infraestrutura Física | L8: Dimensão 7 — Infraestrutura Física | M8: Classificado pela CPA (planilha antiga sem dimensão): infraestrutura tecnológica entra na Dimensão 7 | N8: NOVA | Q8: Não há pergunta de satisfação GERAL com a infraestrutura tecnológica. | R8: 8
A9: 7 | B9: AVALIAÇÃO DOCENTE - VISÃO DO ALUNO 122 | C9: Com relação ao(à) professor(a), avalie de acordo com seu nível de satisfação: | D9: 1- Explicou sobre o Plano de Aprendizagem | E9: Escala de 5 pontos (satisfação) | F9: Muito satisfeito / Satisfeito / Indiferente / Insatisfeito / Muito insatisfeito | G9: 453 | H9: AVALIAÇÃO DO PROFESSOR | I9: Políticas para o Ensino a Pesquisa e a Extensão (2) | J9: 1- Apresentou o Plano de Aula da disciplina (plano de aprendizagem, ementa e objetivos, cronograma) | K9: 3. Políticas Acadêmicas | L9: Dimensão 2 — Ensino, Pesquisa e Extensão | M9: Dimensão da planilha antiga (respeitada) | N9: MUITO PARECIDA | O9: Apresentação do Plano de Aprendizagem da disciplina (ementa, conteúdos, objetivos, cronograma etc) | P9: CPA Atual (por eixo) — linha 17 | R9: 14
A10: 8 | B10: AVALIAÇÃO DOCENTE - VISÃO DO ALUNO 122 | C10: Com relação ao(à) professor(a), avalie de acordo com seu nível de satisfação: | D10: 2 - Planejou e Organizou as aulas | E10: Escala de 5 pontos (satisfação) | F10: Muito satisfeito / Satisfeito / Indiferente / Insatisfeito / Muito insatisfeito | G10: 454 | H10: AVALIAÇÃO DO PROFESSOR | I10: Políticas para o Ensino a Pesquisa e a Extensão (2) | J10: 2- O professor motivou os alunos a aprofundarem seus conhecimentos além do conteúdo apresentado em sala? | K10: 3. Políticas Acadêmicas | L10: Dimensão 2 — Ensino, Pesquisa e Extensão | M10: Dimensão da planilha antiga (respeitada) | N10: NOVA | Q10: Tema próximo apenas para lives: CPA Atual linha 119 ("Organização e preparo das lives"). | R10: 15
A11: 9 | B11: AVALIAÇÃO DOCENTE - VISÃO DO ALUNO 122 | C11: Com relação ao(à) professor(a), avalie de acordo com seu nível de satisfação: | D11: 3 - As avaliações foram coerentes frente aos conteúdos ministrados | E11: Escala de 5 pontos (satisfação) | F11: Muito satisfeito / Satisfeito / Indiferente / Insatisfeito / Muito insatisfeito | G11: 455 | H11: AVALIAÇÃO DO PROFESSOR | I11: Políticas para o Ensino a Pesquisa e a Extensão (2) | J11: 3- As atividades e provas durante o curso estavam de acordo com os assuntos que os professores ensinaram? | K11: 3. Políticas Acadêmicas | L11: Dimensão 2 — Ensino, Pesquisa e Extensão | M11: Dimensão da planilha antiga (respeitada) | N11: MUITO PARECIDA | O11: Aderência das atividades avaliativas aos conteúdos trabalhados em aula | P11: CPA Atual (por eixo) — linha 16 | R11: 16
A12: 10 | B12: AVALIAÇÃO DOCENTE - VISÃO DO ALUNO 122 | C12: Com relação ao(à) professor(a), avalie de acordo com seu nível de satisfação: | D12: 4 - Explicou os critérios de avaliação | E12: Escala de 5 pontos (satisfação) | F12: Muito satisfeito / Satisfeito / Indiferente / Insatisfeito / Muito insatisfeito | G12: 456 | H12: AVALIAÇÃO DO PROFESSOR | I12: Políticas para o Ensino a Pesquisa e a Extensão (2) | J12: manter | K12: 3. Políticas Acadêmicas | L12: Dimensão 2 — Ensino, Pesquisa e Extensão | M12: Dimensão da planilha antiga (respeitada) | N12: MUITO PARECIDA | O12: Explicação dos critérios avaliativos | P12: CPA Atual (por eixo) — linha 20 | R12: 17
A13: 11 | B13: AVALIAÇÃO DOCENTE - VISÃO DO ALUNO 122 | C13: Com relação ao(à) professor(a), avalie de acordo com seu nível de satisfação: | D13: 5 - Se manteve no tema da aula, sem desvios para assuntos irrelevantes | E13: Escala de 5 pontos (satisfação) | F13: Muito satisfeito / Satisfeito / Indiferente / Insatisfeito / Muito insatisfeito | G13: 457 | H13: AVALIAÇÃO DO PROFESSOR | I13: Políticas para o Ensino a Pesquisa e a Extensão (2) | J13: 5 - O professor utilizou exemplos práticos e reais para facilitar a compreensão dos conteúdos? | K13: 3. Políticas Acadêmicas | L13: Dimensão 2 — Ensino, Pesquisa e Extensão | M13: Dimensão da planilha antiga (respeitada) | N13: NOVA | R13: 18
A14: 12 | B14: AVALIAÇÃO DOCENTE - VISÃO DO ALUNO 122 | C14: Com relação ao(à) professor(a), avalie de acordo com seu nível de satisfação: | D14: 6 - Utilizou metodologias diferenciadas e inspiradoras para dinamizar e estimular a participação dos alunos | E14: Escala de 5 pontos (satisfação) | F14: Muito satisfeito / Satisfeito / Indiferente / Insatisfeito / Muito insatisfeito | G14: 459 | H14: AVALIAÇÃO DO PROFESSOR | I14: Políticas para o Ensino a Pesquisa e a Extensão (2) | J14: 6- As aulas foram ministradas de forma dinâmica e envolvente? | K14: 3. Políticas Acadêmicas | L14: Dimensão 2 — Ensino, Pesquisa e Extensão | M14: Dimensão da planilha antiga (respeitada) | N14: MUITO PARECIDA | O14: Dinamismo das aulas | P14: CPA Atual (por eixo) — linha 18 | R14: 19
A15: 13 | B15: AVALIAÇÃO DOCENTE - VISÃO DO ALUNO 122 | C15: Com relação ao(à) professor(a), avalie de acordo com seu nível de satisfação: | D15: 7 - Utilizou o AVA (Ambiente Virtual de Aprendizagem) para disponibilização de conteúdos e recados | E15: Escala de 5 pontos (satisfação) | F15: Muito satisfeito / Satisfeito / Indiferente / Insatisfeito / Muito insatisfeito | G15: 460 | H15: AVALIAÇÃO DO PROFESSOR | I15: Políticas para o Ensino a Pesquisa e a Extensão (2) | J15: manter | K15: 3. Políticas Acadêmicas | L15: Dimensão 2 — Ensino, Pesquisa e Extensão | M15: Dimensão da planilha antiga (respeitada) | N15: MUITO PARECIDA | O15: Utilização do AVA (Ambiente Virtual de Aprendizagem) para disponibilização de conteúdos e comunicados | P15: CPA Atual (por eixo) — linha 23 | Q15: Só muda "recados" → "comunicados". | R15: 20
A16: 14 | B16: AVALIAÇÃO DOCENTE - VISÃO DO ALUNO 122 | C16: Com relação ao(à) professor(a), avalie de acordo com seu nível de satisfação: | D16: 8 - Explicou a importância dos conteúdos para a formação profissional | E16: Escala de 5 pontos (satisfação) | F16: Muito satisfeito / Satisfeito / Indiferente / Insatisfeito / Muito insatisfeito | G16: 461 | H16: AVALIAÇÃO DO PROFESSOR | I16: Políticas para o Ensino a Pesquisa e a Extensão (2) | J16: 8- O professor deu feedbacks construtivos sobre as atividades e avaliações realizadas? | K16: 3. Políticas Acadêmicas | L16: Dimensão 2 — Ensino, Pesquisa e Extensão | M16: Dimensão da planilha antiga (respeitada) | N16: NOVA | Q16: Tema próximo: NEAD - EAD linha 12 e Perguntas Propostas linha 18 (utilidade do conteúdo para a prática profissional), mas lá o foco é o material, não o professor. | R16: 21
A17: 15 | B17: AVALIAÇÃO DOCENTE - VISÃO DO ALUNO 122 | C17: Com relação ao(à) professor(a), avalie de acordo com seu nível de satisfação: | D17: 9 - Auxiliou nas dificuldades apresentadas pelos alunos | E17: Escala de 5 pontos (satisfação) | F17: Muito satisfeito / Satisfeito / Indiferente / Insatisfeito / Muito insatisfeito | G17: 462 | H17: AVALIAÇÃO DO PROFESSOR | I17: Políticas para o Ensino a Pesquisa e a Extensão (2) | J17: 9 - O professor foi acessível e aberto a discussões e questionamentos dos alunos? | K17: 3. Políticas Acadêmicas | L17: Dimensão 2 — Ensino, Pesquisa e Extensão | M17: Dimensão da planilha antiga (respeitada) | N17: NOVA | Q17: Tema próximo: CPA Atual linha 15 (abertura para discussões e questionamentos). | R17: 22
A18: 16 | B18: AVALIAÇÃO DOCENTE - VISÃO DO ALUNO 122 | C18: Com relação ao(à) professor(a), avalie de acordo com seu nível de satisfação: | D18: 10 - Cumpriu datas e horários das aulas | E18: Escala de 5 pontos (satisfação) | F18: Muito satisfeito / Satisfeito / Indiferente / Insatisfeito / Muito insatisfeito | G18: 463 | H18: AVALIAÇÃO DO PROFESSOR | I18: Políticas para o Ensino a Pesquisa e a Extensão (2) | J18: 10- O professor promoveu um ambiente respeitoso e acolhedor em sala de aula? | K18: 3. Políticas Acadêmicas | L18: Dimensão 2 — Ensino, Pesquisa e Extensão | M18: Dimensão da planilha antiga (respeitada) | N18: NOVA | R18: 23
A19: 17 | B19: AVALIAÇÃO DOCENTE - VISÃO DO ALUNO 122 | C19: Com relação ao(à) professor(a), avalie de acordo com seu nível de satisfação: | D19: 11 - Deixe aqui seu(s) comentário(s) sobre a atuação do professor. | E19: Texto livre | F19: Texto livre | G19: 464 | H19: AVALIAÇÃO DO PROFESSOR | I19: Políticas para o Ensino a Pesquisa e a Extensão (2) | K19: 3. Políticas Acadêmicas | L19: Dimensão 2 — Ensino, Pesquisa e Extensão | M19: Dimensão da planilha antiga (respeitada) | N19: MUITO PARECIDA | O19: Deixe aqui seu comentário sobre o(a) professor(a) | P19: CPA Atual (por eixo) — linha 148 | R19: 24
A20: 18 | B20: AMBIENTE VIRTUAL NOS CURSOS PRESENCIAIS - VISÃO DO ALUNO 138 | C20: Com que frequência você acessa às unidades curriculares EAD dos cursos presenciais (por dispositivo): | D20: Celular | E20: revisar — não informado na fonte | F20: Não informado na planilha antiga | K20: Não se aplica / dado de perfil | L20: Não se aplica / dado de perfil | M20: Classificado pela CPA (planilha antiga sem dimensão) | N20: MUITO PARECIDA | O20: Em qual dispositivo você consome a maior parte do conteúdo? | P20: NEAD - EAD — linha 8 | Q20: Lá é "qual dispositivo mais usa" (aluno EAD); aqui é frequência por dispositivo (aluno presencial nas unidades EAD). Na planilha antiga este bloco vem sob a marcação "[NOVA PERGUNTA]" (linha 29). | R20: 31
A21: 19 | B21: AMBIENTE VIRTUAL NOS CURSOS PRESENCIAIS - VISÃO DO ALUNO 138 | C21: Com que frequência você acessa às unidades curriculares EAD dos cursos presenciais (por dispositivo): | D21: Computador | E21: revisar — não informado na fonte | F21: Não informado na planilha antiga | K21: Não se aplica / dado de perfil | L21: Não se aplica / dado de perfil | M21: Classificado pela CPA (planilha antiga sem dimensão) | N21: MUITO PARECIDA | O21: Em qual dispositivo você consome a maior parte do conteúdo? | P21: NEAD - EAD — linha 8 | Q21: Idem linha acima. Na planilha antiga este bloco vem sob a marcação "[NOVA PERGUNTA]" (linha 29). | R21: 32
A22: 20 | B22: AMBIENTE VIRTUAL NOS CURSOS PRESENCIAIS - VISÃO DO ALUNO 138 | C22: Com que frequência você acessa às unidades curriculares EAD dos cursos presenciais (por dispositivo): | D22: Tablet | E22: revisar — não informado na fonte | F22: Não informado na planilha antiga | K22: Não se aplica / dado de perfil | L22: Não se aplica / dado de perfil | M22: Classificado pela CPA (planilha antiga sem dimensão) | N22: MUITO PARECIDA | O22: Em qual dispositivo você consome a maior parte do conteúdo? | P22: NEAD - EAD — linha 8 | Q22: Idem linha acima. Na planilha antiga este bloco vem sob a marcação "[NOVA PERGUNTA]" (linha 29). | R22: 33
A23: 21 | B23: AMBIENTE VIRTUAL NOS CURSOS PRESENCIAIS - VISÃO DO ALUNO 138 | C23: Avalie de acordo com seu nível de satisfação quanto à/ao: | D23: 1 - Com relação ao tempo de atendimento da Equipe de suporte do EAD, sinto-me: | E23: Escala de 5 pontos (satisfação) | F23: Muito satisfeito / Satisfeito / Regular/ Insatisfeito / Muito insatisfeito | G23: 548 | H23: NÚCLEO DE EDUCAÇÃO À DISTÂNCIA - NEAD | I23: Políticas de Atendimento aos Discentes (9) | K23: 3. Políticas Acadêmicas | L23: Dimensão 9 — Atendimento aos Discentes | M23: Dimensão da planilha antiga (respeitada) | N23: NOVA | Q23: Não existe pergunta sobre a Equipe de suporte do EAD. Repete dentro da própria planilha antiga (linha 143). | R23: 39
A24: 22 | B24: AMBIENTE VIRTUAL NOS CURSOS PRESENCIAIS - VISÃO DO ALUNO 138 | C24: Avalie de acordo com seu nível de satisfação quanto à/ao: | D24: 2 - Com relação ao tempo de resposta do Professor-tutor, sinto-me: | E24: Escala de 5 pontos (satisfação) | F24: Muito satisfeito / Satisfeito / Regular/ Insatisfeito / Muito insatisfeito | G24: 547 | H24: NÚCLEO DE EDUCAÇÃO À DISTÂNCIA - NEAD | I24: Políticas de Atendimento aos Discentes (9) | K24: 3. Políticas Acadêmicas | L24: Dimensão 9 — Atendimento aos Discentes | M24: Dimensão da planilha antiga (respeitada) | N24: MUITO PARECIDA | O24: Tempo de resposta do tutor | P24: CPA Atual (por eixo) — linha 140 (repete nas linhas 143 e 146) | R24: 40
A25: 23 | B25: AMBIENTE VIRTUAL NOS CURSOS PRESENCIAIS - VISÃO DO ALUNO 138 | C25: Avalie de acordo com seu nível de satisfação quanto à/ao: | D25: 3 - Com relação às minhas expectativas atendidas pelo AVA - Ambiente Virtual de Aprendizagem, sinto-me: | E25: Escala de 5 pontos (satisfação) | F25: Muito satisfeito / Satisfeito / Regular/ Insatisfeito / Muito insatisfeito | G25: 546 | H25: NÚCLEO DE EDUCAÇÃO À DISTÂNCIA - NEAD | I25: Infraestrutura Virtual (11) | K25: revisar | L25: revisar — "Infraestrutura Virtual (11)" não é uma das 10 dimensões do SINAES | M25: Planilha antiga usa dimensão fora do SINAES | N25: MUITO PARECIDA | O25: Como você avalia a sua experiência de usabilidade da plataforma de estudos - AVA? | P25: NEAD - EAD — linha 18 | Q25: Repete dentro da planilha antiga (linha 144). | R25: 41
A26: 24 | B26: AMBIENTE VIRTUAL NOS CURSOS PRESENCIAIS - VISÃO DO ALUNO 138 | C26: Avalie de acordo com seu nível de satisfação quanto à/ao: | D26: 4 - Com relação ao conteúdo significativo das videoaulas, sinto-me | E26: Escala de 5 pontos (satisfação) | F26: Muito satisfeito / Satisfeito / Regular/ Insatisfeito / Muito insatisfeito | G26: 545 | H26: NÚCLEO DE EDUCAÇÃO À DISTÂNCIA - NEAD | I26: Políticas para o Ensino a Pesquisa e a Extensão (2) | K26: 3. Políticas Acadêmicas | L26: Dimensão 2 — Ensino, Pesquisa e Extensão | M26: Dimensão da planilha antiga (respeitada) | N26: MUITO PARECIDA | O26: Conteúdo das videoaulas Como você avalia a qualidade das videoaulas do professor? Obs.: são os vídeos junto do material escrito, diferente das aulas ao vivo gravadas. | P26: CPA Atual (por eixo) — linha 4 (repete nas linhas 8 e 12) NEAD - EAD — linha 16 | R26: 42
A27: 25 | B27: AMBIENTE VIRTUAL NOS CURSOS PRESENCIAIS - VISÃO DO ALUNO 138 | C27: Avalie de acordo com seu nível de satisfação quanto à/ao: | D27: O tempo de duração das videoaulas foi adequado para a explicação do conteúdo | E27: Escala de 5 pontos (satisfação) | F27: Muito satisfeito / Satisfeito / Regular/ Insatisfeito / Muito insatisfeito | G27: 470 | H27: NÚCLEO DE EDUCAÇÃO À DISTÂNCIA - NEAD | I27: Políticas para o Ensino a Pesquisa e a Extensão (2) | J27: EXCLUIDA | K27: 3. Políticas Acadêmicas | L27: Dimensão 2 — Ensino, Pesquisa e Extensão | M27: Dimensão da planilha antiga (respeitada) | N27: NOVA | Q27: ⚠ Marcada "EXCLUIDA" na planilha antiga. Tema próximo: CPA Atual linha 120 ("Tempo de duração das lives") — lá é live, aqui é videoaula. Já estava marcada como EXCLUIDA na planilha antiga. | R27: 43
A28: 26 | B28: AMBIENTE VIRTUAL NOS CURSOS PRESENCIAIS - VISÃO DO ALUNO 138 | C28: Avalie de acordo com seu nível de satisfação quanto à/ao: | D28: 5 - Com relação aos materiais escritos (textos, infográficos, mapas etc.), estou: | E28: Escala de 5 pontos (satisfação) | F28: Muito satisfeito / Satisfeito / Regular/ Insatisfeito / Muito insatisfeito | G28: 544 | H28: NÚCLEO DE EDUCAÇÃO À DISTÂNCIA - NEAD | I28: Políticas para o Ensino a Pesquisa e a Extensão (2) | K28: 3. Políticas Acadêmicas | L28: Dimensão 2 — Ensino, Pesquisa e Extensão | M28: Dimensão da planilha antiga (respeitada) | N28: MUITO PARECIDA | O28: Materiais escritos (textos, infográficos, mapas etc.) | P28: CPA Atual (por eixo) — linha 6 (repete nas linhas 10 e 14) | Q28: Mesmo item; muda só o enunciado. | R28: 44
A29: 27 | B29: AMBIENTE VIRTUAL NOS CURSOS PRESENCIAIS - VISÃO DO ALUNO 138 | C29: Avalie de acordo com seu nível de satisfação quanto à/ao: | D29: 6 - Quando utilizo meu COMPUTADOR/NOTEBOOK para acessar as minhas disciplinas EAD, sinto-me: | E29: Escala de 5 pontos (satisfação) | F29: Muito satisfeito / Satisfeito / Regular/ Insatisfeito / Muito insatisfeito | G29: 543 | H29: NÚCLEO DE EDUCAÇÃO À DISTÂNCIA - NEAD | I29: Infraestrutura Virtual (11) | K29: revisar | L29: revisar — "Infraestrutura Virtual (11)" não é uma das 10 dimensões do SINAES | M29: Planilha antiga usa dimensão fora do SINAES | N29: NOVA | Q29: Tema próximo: NEAD - EAD linhas 7 e 8 (dificuldade técnica / dispositivo). Repete na planilha antiga (linha 145). | R29: 45
A30: 28 | B30: AMBIENTE VIRTUAL NOS CURSOS PRESENCIAIS - VISÃO DO ALUNO 138 | C30: Avalie de acordo com seu nível de satisfação quanto à/ao: | D30: 7 - Quando utilizo o CELULAR/TABLET para acessar as minhas disciplinas EAD, sinto-me: | E30: Escala de 5 pontos (satisfação) | F30: Muito satisfeito / Satisfeito / Regular/ Insatisfeito / Muito insatisfeito | G30: 542 | H30: NÚCLEO DE EDUCAÇÃO À DISTÂNCIA - NEAD | I30: Infraestrutura Virtual (11) | K30: revisar | L30: revisar — "Infraestrutura Virtual (11)" não é uma das 10 dimensões do SINAES | M30: Planilha antiga usa dimensão fora do SINAES | N30: NOVA | Q30: Tema próximo: NEAD - EAD linhas 7 e 8. Repete na planilha antiga (linha 146). | R30: 46
A31: 29 | B31: AMBIENTE VIRTUAL NOS CURSOS PRESENCIAIS - VISÃO DO ALUNO 138 | C31: Avalie de acordo com seu nível de satisfação quanto à/ao: | D31: 8 - Com relação à visualização e localização dos conteúdos na plataforma, estou: | E31: Escala de 5 pontos (satisfação) | F31: Muito satisfeito / Satisfeito / Regular/ Insatisfeito / Muito insatisfeito | G31: 541 | H31: NÚCLEO DE EDUCAÇÃO À DISTÂNCIA - NEAD | I31: Infraestrutura Virtual (11) | K31: revisar | L31: revisar — "Infraestrutura Virtual (11)" não é uma das 10 dimensões do SINAES | M31: Planilha antiga usa dimensão fora do SINAES | N31: MUITO PARECIDA | O31: No Ambiente Virtual de Aprendizagem (AVA), quão fácil foi encontrar o que você precisava? | P31: NEAD - EAD — linha 9 | Q31: Repete na planilha antiga (linha 147). | R31: 47
A32: 30 | B32: AMBIENTE VIRTUAL NOS CURSOS PRESENCIAIS - VISÃO DO ALUNO 138 | C32: Avalie de acordo com seu nível de satisfação quanto à/ao: | D32: 9 - Se desejar deixe aqui seus comentários sobre a Infraestrutura Virtual: | E32: Texto livre | F32: Texto livre | G32: 246 | H32: INFRAESTRUTURA TECNOLÓGICA | I32: Infraestrutura Virtual (11) | K32: revisar | L32: revisar — "Infraestrutura Virtual (11)" não é uma das 10 dimensões do SINAES | M32: Planilha antiga usa dimensão fora do SINAES | N32: NOVA | Q32: Não há campo aberto específico de infraestrutura VIRTUAL (o da CPA Atual linha 149 é de infraestrutura física e serviços). | R32: 48
A33: 31 | B33: PLANEJAMENTO E DESENVOLVIMENTO INSTITUCIONAL - VISÃO DO ALUNO 135 | C33: Indique o seu nível conhecimento sobre cada tópico: | D33: 1 - Nota do meu curso no MEC | E33: Escala de 5 pontos (conhecimento) | F33: Conheço muito bem/ Conheço bem/ Conheço/ Conheço pouco/ Desconheço | G33: 465 | H33: PLANEJAMENTO INSTITUCIONAL | I33: Missão e PDI (1) | K33: 2. Desenvolvimento Institucional | L33: Dimensão 1 — Missão e PDI | M33: Dimensão da planilha antiga (respeitada) | N33: NOVA | R33: 55
A34: 32 | B34: PLANEJAMENTO E DESENVOLVIMENTO INSTITUCIONAL - VISÃO DO ALUNO 135 | C34: Indique o seu nível conhecimento sobre cada tópico: | D34: 2 - Ações de responsabilidade social desenvolvidas pela UniFECAF | E34: Escala de 5 pontos (conhecimento) | F34: Conheço muito bem/ Conheço bem/ Conheço/ Conheço pouco/ Desconheço | G34: 475 | H34: PLANEJAMENTO INSTITUCIONAL | I34: Responsabilidade Social (3) | K34: 2. Desenvolvimento Institucional | L34: Dimensão 3 — Responsabilidade Social | M34: Dimensão da planilha antiga (respeitada) | N34: MUITO PARECIDA | O34: Você conhece alguma ação de responsabilidade social promovida pela UniFECAF neste semestre? | P34: Perguntas Propostas por Eixo — linha 14 (pergunta candidata) | R34: 56
A35: 33 | B35: PLANEJAMENTO E DESENVOLVIMENTO INSTITUCIONAL - VISÃO DO ALUNO 135 | C35: Indique o seu nível conhecimento sobre cada tópico: | D35: 3 - Programas de Bolsa de Estudos e de Financiamento da UniFECAF | E35: Escala de 5 pontos (conhecimento) | F35: Conheço muito bem/ Conheço bem/ Conheço/ Conheço pouco/ Desconheço | G35: 476 | H35: PLANEJAMENTO INSTITUCIONAL | I35: Políticas para o Ensino a Pesquisa e a Extensão (2) | K35: 3. Políticas Acadêmicas | L35: Dimensão 2 — Ensino, Pesquisa e Extensão | M35: Dimensão da planilha antiga (respeitada) | N35: MUITO PARECIDA | O35: Como você avalia as políticas de inclusão e acesso da faculdade (bolsas, FIES/PROUNI, financiamento estudantil)? | P35: Perguntas Propostas por Eixo — linha 12 (pergunta candidata) | Q35: Lá avalia a política; aqui mede o conhecimento sobre ela. | R35: 57
A36: 34 | B36: PLANEJAMENTO E DESENVOLVIMENTO INSTITUCIONAL - VISÃO DO ALUNO 135 | C36: Indique o seu nível conhecimento sobre cada tópico: | D36: 4 - Matriz Curricular do meu curso | E36: Escala de 5 pontos (conhecimento) | F36: Conheço muito bem/ Conheço bem/ Conheço/ Conheço pouco/ Desconheço | G36: 477 | H36: PLANEJAMENTO INSTITUCIONAL | I36: Planejamento e Avaliação (8) | K36: 1. Planejamento e Avaliação Institucional | L36: Dimensão 8 — Planejamento e Avaliação | M36: Dimensão da planilha antiga (respeitada) | N36: NOVA | Q36: Tema próximo: Perguntas Propostas linha 8 (PPC). | R36: 58
A37: 35 | B37: PLANEJAMENTO E DESENVOLVIMENTO INSTITUCIONAL - VISÃO DO ALUNO 135 | C37: Indique o seu nível conhecimento sobre cada tópico: | D37: 5 - Projeto Pedagógico do Curso - PPC do meu curso | E37: Escala de 5 pontos (conhecimento) | F37: Conheço muito bem/ Conheço bem/ Conheço/ Conheço pouco/ Desconheço | G37: 478 | H37: PLANEJAMENTO INSTITUCIONAL | I37: Planejamento e Avaliação (8) | K37: 1. Planejamento e Avaliação Institucional | L37: Dimensão 8 — Planejamento e Avaliação | M37: Dimensão da planilha antiga (respeitada) | N37: MUITO PARECIDA | O37: Como você avalia seu conhecimento sobre o Projeto Pedagógico (PPC) do seu curso? | P37: Perguntas Propostas por Eixo — linha 8 (pergunta candidata) | R37: 59
A38: 36 | B38: PLANEJAMENTO E DESENVOLVIMENTO INSTITUCIONAL - VISÃO DO ALUNO 135 | C38: Indique o seu nível conhecimento sobre cada tópico: | D38: 6 - Ouvidoria da UniFECAF | E38: Escala de 5 pontos (conhecimento) | F38: Conheço muito bem/ Conheço bem/ Conheço/ Conheço pouco/ Desconheço | G38: 479 | H38: PLANEJAMENTO INSTITUCIONAL | I38: Planejamento e Avaliação (8) | K38: 1. Planejamento e Avaliação Institucional | L38: Dimensão 8 — Planejamento e Avaliação | M38: Dimensão da planilha antiga (respeitada) | N38: MUITO PARECIDA | O38: Você sabe como registrar uma reclamação, sugestão ou elogio formal à faculdade (ouvidoria)? | P38: Perguntas Propostas por Eixo — linha 22 (pergunta candidata) | R38: 60
A39: 37 | B39: PLANEJAMENTO E DESENVOLVIMENTO INSTITUCIONAL - VISÃO DO ALUNO 135 | C39: Indique o seu nível conhecimento sobre cada tópico: | D39: 7 - Resultados da Comissão Própria de Avaliação (CPA) | E39: Escala de 5 pontos (conhecimento) | F39: Conheço muito bem/ Conheço bem/ Conheço/ Conheço pouco/ Desconheço | G39: 480 | H39: PLANEJAMENTO INSTITUCIONAL | I39: Planejamento e Avaliação (8) | K39: 1. Planejamento e Avaliação Institucional | L39: Dimensão 8 — Planejamento e Avaliação | M39: Dimensão da planilha antiga (respeitada) | N39: MUITO PARECIDA | O39: Como você avalia a clareza e a frequência com que os resultados e ações da CPA são divulgados para os alunos? Você sabe que a UniFECAF tem uma Comissão Própria de Avaliação (CPA) que analisa as respostas desta pesquisa? | P39: Perguntas Propostas por Eixo — linha 21 (pergunta candidata) Perguntas Propostas por Eixo — linha 3 (pergunta candidata) | R39: 61
A40: 38 | B40: PLANEJAMENTO E DESENVOLVIMENTO INSTITUCIONAL - VISÃO DO ALUNO 135 | C40: Indique o seu nível conhecimento sobre cada tópico: | D40: 8 - Núcleo de Atendimento Psicopedagógico - NAP | E40: Escala de 5 pontos (conhecimento) | F40: Conheço muito bem/ Conheço bem/ Conheço/ Conheço pouco/ Desconheço | G40: 481 | H40: PLANEJAMENTO INSTITUCIONAL | I40: Planejamento e Avaliação (8) | K40: 1. Planejamento e Avaliação Institucional | L40: Dimensão 8 — Planejamento e Avaliação | M40: Dimensão da planilha antiga (respeitada) | N40: MUITO PARECIDA | O40: Como você avalia o apoio psicológico/psicopedagógico oferecido pela faculdade? | P40: Perguntas Propostas por Eixo — linha 23 (pergunta candidata) | Q40: Lá avalia o apoio; aqui mede o conhecimento sobre o NAP. | R40: 62
...

Sheet Página1
A1: Eixo | B1: Dimensão | C1: Perguntas | D1: Situação
A2: 1 — Planejamento e Avaliação | B2: 8 — Planejamento e Avaliação | C2: 1 | D2: Coberta, mas fraca (só "Recomenda a UniFECAF…")
A3: 2 — Desenvolvimento Institucional | B3: 1 — Missão e PDI | C3: 0 | D3: Sem pergunta
B4: 3 — Responsabilidade Social | C4: 1 | D4: Coberta, mas fraca (só "Atuação… em projetos sociais")
A5: 3 — Políticas Acadêmicas | B5: 2 — Ensino, Pesquisa e Extensão | C5: 29 | D5: Muito coberta (conteúdos, docente, lives, tutores)
B6: 4 — Comunicação com a Sociedade | C6: 1 | D6: Coberta, mas fraca (só redes sociais)
B7: 9 — Atendimento aos Discentes | C7: 3 | D7: Coberta (Acolhimento, Agiliza, Carreiras)
B8: revisar (4 ou 9 / bloco misto) | C8: 3 | D8: "Comunicação entre alunos e coordenador" + 2 campos de comentário
A9: 4 — Políticas de Gestão | B9: 5 — Políticas de Pessoal | C9: 0 | D9: Sem pergunta
B10: 6 — Organização e Gestão | C10: 8 | D10: Coberta (tudo sobre coordenação de curso)
B11: 10 — Sustentabilidade Financeira | C11: 0 | D11: Sem pergunta
A12: 5 — Infraestrutura Física | B12: 7 — Infraestrutura Física | C12: 19 | D12: Muito coberta

